<?xml version="1.0" encoding="UTF-8"?>
<!-- Generated by org.testng.reporters.JUnitReportReporter -->
<testsuite skipped="8" hostname="DESKTOP-16VI708" name="com.naveentestNG.RetryLogic2" tests="11" failures="2" timestamp="07 Dec 2017 08:15:34 GMT" time="0.050" errors="0">
  <testcase name="testCase3" time="0.002" classname="com.naveentestNG.RetryLogic2"/>
  <testcase name="testCase1" time="0.022" classname="com.naveentestNG.RetryLogic2">
    <skipped/>
  </testcase> <!-- testCase1 -->
  <testcase name="testCase2" time="0.002" classname="com.naveentestNG.RetryLogic2">
    <skipped/>
  </testcase> <!-- testCase2 -->
  <testcase name="testCase2" time="0.001" classname="com.naveentestNG.RetryLogic2">
    <failure type="java.lang.AssertionError" message="expected [false] but found [true]">
      <![CDATA[java.lang.AssertionError: expected [false] but found [true]
	at org.testng.Assert.fail(Assert.java:93)
	at org.testng.Assert.failNotEquals(Assert.java:512)
	at org.testng.Assert.assertEqualsImpl(Assert.java:134)
	at org.testng.Assert.assertEquals(Assert.java:115)
	at org.testng.Assert.assertEquals(Assert.java:304)
	at org.testng.Assert.assertEquals(Assert.java:314)
	at com.naveentestNG.RetryLogic2.testCase2(RetryLogic2.java:15)
	at sun.reflect.NativeMethodAccessorImpl.invoke0(Native Method)
	at sun.reflect.NativeMethodAccessorImpl.invoke(Unknown Source)
	at sun.reflect.DelegatingMethodAccessorImpl.invoke(Unknown Source)
	at java.lang.reflect.Method.invoke(Unknown Source)
	at org.testng.internal.MethodInvocationHelper.invokeMethod(MethodInvocationHelper.java:108)
	at org.testng.internal.Invoker.invokeMethod(Invoker.java:661)
	at org.testng.internal.Invoker.retryFailed(Invoker.java:1014)
	at org.testng.internal.Invoker.invokeTestMethods(Invoker.java:1215)
	at org.testng.internal.TestMethodWorker.invokeTestMethods(TestMethodWorker.java:126)
	at org.testng.internal.TestMethodWorker.run(TestMethodWorker.java:109)
	at org.testng.TestRunner.privateRun(TestRunner.java:744)
	at org.testng.TestRunner.run(TestRunner.java:602)
	at org.testng.SuiteRunner.runTest(SuiteRunner.java:380)
	at org.testng.SuiteRunner.runSequentially(SuiteRunner.java:375)
	at org.testng.SuiteRunner.privateRun(SuiteRunner.java:340)
	at org.testng.SuiteRunner.run(SuiteRunner.java:289)
	at org.testng.SuiteRunnerWorker.runSuite(SuiteRunnerWorker.java:52)
	at org.testng.SuiteRunnerWorker.run(SuiteRunnerWorker.java:86)
	at org.testng.TestNG.runSuitesSequentially(TestNG.java:1301)
	at org.testng.TestNG.runSuitesLocally(TestNG.java:1226)
	at org.testng.TestNG.runSuites(TestNG.java:1144)
	at org.testng.TestNG.run(TestNG.java:1115)
	at org.testng.remote.AbstractRemoteTestNG.run(AbstractRemoteTestNG.java:114)
	at org.testng.remote.RemoteTestNG.initAndRun(RemoteTestNG.java:251)
	at org.testng.remote.RemoteTestNG.main(RemoteTestNG.java:77)
]]>
    </failure>
  </testcase> <!-- testCase2 -->
  <testcase name="testCase2" time="0.009" classname="com.naveentestNG.RetryLogic2">
    <skipped/>
  </testcase> <!-- testCase2 -->
  <testcase name="testCase1" time="0.004" classname="com.naveentestNG.RetryLogic2">
    <failure type="java.lang.AssertionError" message="expected [false] but found [true]">
      <![CDATA[java.lang.AssertionError: expected [false] but found [true]
	at org.testng.Assert.fail(Assert.java:93)
	at org.testng.Assert.failNotEquals(Assert.java:512)
	at org.testng.Assert.assertEqualsImpl(Assert.java:134)
	at org.testng.Assert.assertEquals(Assert.java:115)
	at org.testng.Assert.assertEquals(Assert.java:304)
	at org.testng.Assert.assertEquals(Assert.java:314)
	at com.naveentestNG.RetryLogic2.testCase1(RetryLogic2.java:10)
	at sun.reflect.NativeMethodAccessorImpl.invoke0(Native Method)
	at sun.reflect.NativeMethodAccessorImpl.invoke(Unknown Source)
	at sun.reflect.DelegatingMethodAccessorImpl.invoke(Unknown Source)
	at java.lang.reflect.Method.invoke(Unknown Source)
	at org.testng.internal.MethodInvocationHelper.invokeMethod(MethodInvocationHelper.java:108)
	at org.testng.internal.Invoker.invokeMethod(Invoker.java:661)
	at org.testng.internal.Invoker.retryFailed(Invoker.java:1014)
	at org.testng.internal.Invoker.invokeTestMethods(Invoker.java:1215)
	at org.testng.internal.TestMethodWorker.invokeTestMethods(TestMethodWorker.java:126)
	at org.testng.internal.TestMethodWorker.run(TestMethodWorker.java:109)
	at org.testng.TestRunner.privateRun(TestRunner.java:744)
	at org.testng.TestRunner.run(TestRunner.java:602)
	at org.testng.SuiteRunner.runTest(SuiteRunner.java:380)
	at org.testng.SuiteRunner.runSequentially(SuiteRunner.java:375)
	at org.testng.SuiteRunner.privateRun(SuiteRunner.java:340)
	at org.testng.SuiteRunner.run(SuiteRunner.java:289)
	at org.testng.SuiteRunnerWorker.runSuite(SuiteRunnerWorker.java:52)
	at org.testng.SuiteRunnerWorker.run(SuiteRunnerWorker.java:86)
	at org.testng.TestNG.runSuitesSequentially(TestNG.java:1301)
	at org.testng.TestNG.runSuitesLocally(TestNG.java:1226)
	at org.testng.TestNG.runSuites(TestNG.java:1144)
	at org.testng.TestNG.run(TestNG.java:1115)
	at org.testng.remote.AbstractRemoteTestNG.run(AbstractRemoteTestNG.java:114)
	at org.testng.remote.RemoteTestNG.initAndRun(RemoteTestNG.java:251)
	at org.testng.remote.RemoteTestNG.main(RemoteTestNG.java:77)
]]>
    </failure>
  </testcase> <!-- testCase1 -->
  <testcase name="testCase1" time="0.002" classname="com.naveentestNG.RetryLogic2">
    <skipped/>
  </testcase> <!-- testCase1 -->
  <testcase name="testCase1" time="0.003" classname="com.naveentestNG.RetryLogic2">
    <skipped/>
  </testcase> <!-- testCase1 -->
  <testcase name="testCase2" time="0.001" classname="com.naveentestNG.RetryLogic2">
    <skipped/>
  </testcase> <!-- testCase2 -->
  <testcase name="testCase1" time="0.002" classname="com.naveentestNG.RetryLogic2">
    <skipped/>
  </testcase> <!-- testCase1 -->
  <testcase name="testCase2" time="0.002" classname="com.naveentestNG.RetryLogic2">
    <skipped/>
  </testcase> <!-- testCase2 -->
</testsuite> <!-- com.naveentestNG.RetryLogic2 -->
